Workbook
Name \a: #N/A
Name \b: #N/A
Name \c: #N/A
Name \d: #N/A
Name \e: #N/A
Name \f: #N/A
Name \g: #N/A
Name \h: #N/A
Name \i: #N/A
Name \j: #N/A
Name \m: #N/A
Name \p: #N/A
Name \q: #N/A
Name \r: #N/A
Name \s: #N/A
Name \t: #N/A
Name \u: #N/A
Name \v: #N/A
Name \w: #N/A
Name \x: #N/A
Name \z: #N/A
Name ____FOL2: #REF!
Name ____tab1: #REF!
Name ___cab1: #REF!
Name ___cab2: #REF!
Name ___FOL3: #N/A
Name ___FOL4: #N/A
Name ___LUP1: #N/A
Name ___LUP2: #N/A
Name ___ORC98: #REF!
Name ___pla1: #REF!
Name ___R: #N/A
Name ___TOT1: #REF!
Name ___TOT2: #REF!
Name ___TOT3: #REF!
Name ___TOT4: #REF!
Name ___TOT5: #REF!
Name ___TOT6: #REF!
Name ___TOT7: #REF!
Name ___VV9: #REF!
Name __cab1: #REF!
Name __cab2: #REF!
Name __FOL2: #REF!
Name __FOL3: #N/A
Name __FOL4: #N/A
Name __LUP1: #N/A
Name __LUP2: #N/A
Name __ORC98: #REF!
Name __pla1: #REF!
Name __R: #N/A
Name __tab1: #REF!
Name __TOT1: #REF!
Name __TOT2: #REF!
Name __TOT3: #REF!
Name __TOT4: #REF!
Name __TOT5: #REF!
Name __TOT6: #REF!
Name __TOT7: #REF!
Name __VV9: #REF!
Name _164: #N/A

Sheet ENTRADA
C1: =IF(ISBLANK(#REF!),"",IFERROR(VLOOKUP(#REF!,ESTOQUE!$B$2:$M$997973,2,FALSE),"Produto não cadastrado")) -> Produto não cadastrado
A2: Data | B2: Cod | C2: GRUPO | D2: Descrição | E2: UN. | F2: Quant | G2: Valor unit | H2: CUSTO | I2: Fornecedor | J2: Nº N.F | K2: Observação
A3: 45678 | B3: 122 | C3: =IF(ISBLANK($B3),"",IFERROR(VLOOKUP($B3,ESTOQUE!$B$2:$D$97168,2,FALSE),"Produto não cadastrado")) -> CONSUMO | D3: =IF(ISBLANK($B3),"",IFERROR(VLOOKUP($B3,ESTOQUE!$B$2:$M$997973,3,FALSE),"Produto não cadastrado")) -> SUPORTE PROTETOR FACIAL | E3: =_xlfn.XLOOKUP(B3,ESTOQUE!B:B,ESTOQUE!G:G) -> UND | F3: 1 | H3: =F3*G3 -> 0
A4: 45929 | B4: 2 | C4: =IF(ISBLANK($B4),"",IFERROR(VLOOKUP($B4,ESTOQUE!$B$2:$D$97168,2,FALSE),"Produto não cadastrado")) -> CONSUMO | D4: =IF(ISBLANK($B4),"",IFERROR(VLOOKUP($B4,ESTOQUE!$B$2:$M$997973,3,FALSE),"Produto não cadastrado")) -> AVENTAL DE RASPA TAM 1X60MT | E4: =_xlfn.XLOOKUP(B4,ESTOQUE!B:B,ESTOQUE!G:G) -> UND | F4: 20 | G4: 49 | H4: =F4*G4 -> 980 | K4: Ajuste de estoque conforme inventário
A5: 45929 | B5: 228 | C5: =IF(ISBLANK($B5),"",IFERROR(VLOOKUP($B5,ESTOQUE!$B$2:$D$97168,2,FALSE),"Produto não cadastrado")) -> CONSUMO | D5: =IF(ISBLANK($B5),"",IFERROR(VLOOKUP($B5,ESTOQUE!$B$2:$M$997973,3,FALSE),"Produto não cadastrado")) -> BALACLAVA | E5: =_xlfn.XLOOKUP(B5,ESTOQUE!B:B,ESTOQUE!G:G) -> UND | F5: 250 | G5: 18.9 | H5: =F5*G5 -> 4725 | K5: Ajuste de estoque conforme inventário
A6: 45929 | B6: 4 | C6: =IF(ISBLANK($B6),"",IFERROR(VLOOKUP($B6,ESTOQUE!$B$2:$D$97168,2,FALSE),"Produto não cadastrado")) -> CONSUMO | D6: =IF(ISBLANK($B6),"",IFERROR(VLOOKUP($B6,ESTOQUE!$B$2:$M$997973,3,FALSE),"Produto não cadastrado")) -> BLUSÃO DE RASPA MANGA LONGA | E6: =_xlfn.XLOOKUP(B6,ESTOQUE!B:B,ESTOQUE!G:G) -> UND | F6: 1 | G6: 91.82 | H6: =F6*G6 -> 91.82 | K6: Ajuste de estoque conforme inventário
A7: 45929 | B7: 16 | C7: =IF(ISBLANK($B7),"",IFERROR(VLOOKUP($B7,ESTOQUE!$B$2:$D$97168,2,FALSE),"Produto não cadastrado")) -> CONSUMO | D7: =IF(ISBLANK($B7),"",IFERROR(VLOOKUP($B7,ESTOQUE!$B$2:$M$997973,3,FALSE),"Produto não cadastrado")) -> BOTA PVC CANO MEDIO Nº 37 | E7: =_xlfn.XLOOKUP(B7,ESTOQUE!B:B,ESTOQUE!G:G) -> PAR | F7: 5 | G7: 34.9 | H7: =F7*G7 -> 174.5 | K7: Ajuste de estoque conforme inventário
A8: 45929 | B8: 17 | C8: =IF(ISBLANK($B8),"",IFERROR(VLOOKUP($B8,ESTOQUE!$B$2:$D$97168,2,FALSE),"Produto não cadastrado")) -> CONSUMO | D8: =IF(ISBLANK($B8),"",IFERROR(VLOOKUP($B8,ESTOQUE!$B$2:$M$997973,3,FALSE),"Produto não cadastrado")) -> BOTA PVC CANO MEDIO Nº 38 | E8: =_xlfn.XLOOKUP(B8,ESTOQUE!B:B,ESTOQUE!G:G) -> PAR | F8: 2 | G8: 34.9 | H8: =F8*G8 -> 69.8 | K8: Ajuste de estoque conforme inventário
A9: 45929 | B9: 7 | C9: =IF(ISBLANK($B9),"",IFERROR(VLOOKUP($B9,ESTOQUE!$B$2:$D$97168,2,FALSE),"Produto não cadastrado")) -> CONSUMO | D9: =IF(ISBLANK($B9),"",IFERROR(VLOOKUP($B9,ESTOQUE!$B$2:$M$997973,3,FALSE),"Produto não cadastrado")) -> BOTA PVC CANO LONGO Nº 39 | E9: =_xlfn.XLOOKUP(B9,ESTOQUE!B:B,ESTOQUE!G:G) -> PAR | F9: 4 | G9: 56.3 | H9: =F9*G9 -> 225.2 | K9: Ajuste de estoque conforme inventário
A10: 45929 | B10: 10 | C10: =IF(ISBLANK($B10),"",IFERROR(VLOOKUP($B10,ESTOQUE!$B$2:$D$97168,2,FALSE),"Produto não cadastrado")) -> CONSUMO | D10: BOTA PVC CANO LONGO Nº 42 | E10: =_xlfn.XLOOKUP(B10,ESTOQUE!B:B,ESTOQUE!G:G) -> PAR | F10: 8 | G10: 56.3 | H10: =F10*G10 -> 450.4 | K10: Ajuste de estoque conforme inventário
A11: 45929 | B11: 11 | C11: =IF(ISBLANK($B11),"",IFERROR(VLOOKUP($B11,ESTOQUE!$B$2:$D$97168,2,FALSE),"Produto não cadastrado")) -> CONSUMO | D11: =D18 -> BOTINA OP. BICO PVC Nº 38 | E11: =_xlfn.XLOOKUP(B11,ESTOQUE!B:B,ESTOQUE!G:G) -> PAR | F11: 12 | G11: 56.3 | H11: =F11*G11 -> 675.6 | K11: Ajuste de estoque conforme inventário
A12: 45929 | B12: 12 | C12: =IF(ISBLANK($B12),"",IFERROR(VLOOKUP($B12,ESTOQUE!$B$2:$D$97168,2,FALSE),"Produto não cadastrado")) -> CONSUMO | D12: =IF(ISBLANK($B12),"",IFERROR(VLOOKUP($B12,ESTOQUE!$B$2:$M$997973,3,FALSE),"Produto não cadastrado")) -> BOTA PVC CANO LONGO Nº 44 | E12: =_xlfn.XLOOKUP(B12,ESTOQUE!B:B,ESTOQUE!G:G) -> PAR | F12: 1 | G12: 56.3 | H12: =F12*G12 -> 56.3 | K12: Ajuste de estoque conforme inventário
A13: 45929 | B13: 13 | C13: =IF(ISBLANK($B13),"",IFERROR(VLOOKUP($B13,ESTOQUE!$B$2:$D$97168,2,FALSE),"Produto não cadastrado")) -> CONSUMO | D13: =IF(ISBLANK($B13),"",IFERROR(VLOOKUP($B13,ESTOQUE!$B$2:$M$997973,3,FALSE),"Produto não cadastrado")) -> BOTA PVC CANO LONGO Nº 45 | E13: =_xlfn.XLOOKUP(B13,ESTOQUE!B:B,ESTOQUE!G:G) -> PAR | F13: 10 | G13: 56.3 | H13: =F13*G13 -> 563 | K13: Ajuste de estoque conforme inventário
A14: 45929 | B14: 14 | C14: =IF(ISBLANK($B14),"",IFERROR(VLOOKUP($B14,ESTOQUE!$B$2:$D$97168,2,FALSE),"Produto não cadastrado")) -> CONSUMO | D14: =IF(ISBLANK($B14),"",IFERROR(VLOOKUP($B14,ESTOQUE!$B$2:$M$997973,3,FALSE),"Produto não cadastrado")) -> BOTA PVC CANO LONGO Nº 46 | E14: =_xlfn.XLOOKUP(B14,ESTOQUE!B:B,ESTOQUE!G:G) -> PAR | F14: 1 | G14: 56.3 | H14: =F14*G14 -> 56.3 | K14: Ajuste de estoque conforme inventário
A15: 45929 | B15: 19 | C15: =IF(ISBLANK($B15),"",IFERROR(VLOOKUP($B15,ESTOQUE!$B$2:$D$97168,2,FALSE),"Produto não cadastrado")) -> CONSUMO | D15: =IF(ISBLANK($B15),"",IFERROR(VLOOKUP($B15,ESTOQUE!$B$2:$M$997973,3,FALSE),"Produto não cadastrado")) -> BOTA PVC CANO MEDIO Nº 40 | E15: =_xlfn.XLOOKUP(B15,ESTOQUE!B:B,ESTOQUE!G:G) -> PAR | F15: 6 | G15: 34.9 | H15: =F15*G15 -> 209.4 | K15: Ajuste de estoque conforme inventário
A16: 45929 | B16: 20 | C16: =IF(ISBLANK($B16),"",IFERROR(VLOOKUP($B16,ESTOQUE!$B$2:$D$97168,2,FALSE),"Produto não cadastrado")) -> CONSUMO | D16: =IF(ISBLANK($B16),"",IFERROR(VLOOKUP($B16,ESTOQUE!$B$2:$M$997973,3,FALSE),"Produto não cadastrado")) -> BOTA PVC CANO MEDIO Nº 41 | E16: =_xlfn.XLOOKUP(B16,ESTOQUE!B:B,ESTOQUE!G:G) -> PAR | F16: 14 | G16: 34.9 | H16: =F16*G16 -> 488.6 | K16: Ajuste de estoque conforme inventário
A17: 45929 | B17: 34 | C17: =IF(ISBLANK($B17),"",IFERROR(VLOOKUP($B17,ESTOQUE!$B$2:$D$97168,2,FALSE),"Produto não cadastrado")) -> CONSUMO | D17: =IF(ISBLANK($B17),"",IFERROR(VLOOKUP($B17,ESTOQUE!$B$2:$M$997973,3,FALSE),"Produto não cadastrado")) -> BOTINA OP. BICO PVC Nº 36 | E17: =_xlfn.XLOOKUP(B17,ESTOQUE!B:B,ESTOQUE!G:G) -> PAR | F17: 5 | G17: 62.7 | H17: =F17*G17 -> 313.5 | K17: Ajuste de estoque conforme inventário
A18: 45929 | B18: 36 | C18: =IF(ISBLANK($B18),"",IFERROR(VLOOKUP($B18,ESTOQUE!$B$2:$D$97168,2,FALSE),"Produto não cadastrado")) -> CONSUMO | D18: =IF(ISBLANK($B18),"",IFERROR(VLOOKUP($B18,ESTOQUE!$B$2:$M$997973,3,FALSE),"Produto não cadastrado")) -> BOTINA OP. BICO PVC Nº 38 | E18: =_xlfn.XLOOKUP(B18,ESTOQUE!B:B,ESTOQUE!G:G) -> PAR | F18: 10 | G18: 62.7 | H18: =F18*G18 -> 627 | K18: Ajuste de estoque conforme inventário
A19: 45929 | B19: 37 | C19: =IF(ISBLANK($B19),"",IFERROR(VLOOKUP($B19,ESTOQUE!$B$2:$D$97168,2,FALSE),"Produto não cadastrado")) -> CONSUMO | D19: =IF(ISBLANK($B19),"",IFERROR(VLOOKUP($B19,ESTOQUE!$B$2:$M$997973,3,FALSE),"Produto não cadastrado")) -> BOTINA OP. BICO PVC Nº 39 | E19: =_xlfn.XLOOKUP(B19,ESTOQUE!B:B,ESTOQUE!G:G) -> PAR | F19: 9 | G19: 62.7 | H19: =F19*G19 -> 564.3 | K19: Ajuste de estoque conforme inventário
A20: 45929 | B20: 38 | C20: =IF(ISBLANK($B20),"",IFERROR(VLOOKUP($B20,ESTOQUE!$B$2:$D$97168,2,FALSE),"Produto não cadastrado")) -> CONSUMO | D20: =IF(ISBLANK($B20),"",IFERROR(VLOOKUP($B20,ESTOQUE!$B$2:$M$997973,3,FALSE),"Produto não cadastrado")) -> BOTINA OP. BICO PVC Nº 40 | E20: =_xlfn.XLOOKUP(B20,ESTOQUE!B:B,ESTOQUE!G:G) -> PAR | F20: 32 | G20: 62.7 | H20: =F20*G20 -> 2006.4 | K20: Ajuste de estoque conforme inventário
A21: 45929 | B21: 39 | C21: =IF(ISBLANK($B21),"",IFERROR(VLOOKUP($B21,ESTOQUE!$B$2:$D$97168,2,FALSE),"Produto não cadastrado")) -> CONSUMO | D21: =IF(ISBLANK($B21),"",IFERROR(VLOOKUP($B21,ESTOQUE!$B$2:$M$997973,3,FALSE),"Produto não cadastrado")) -> BOTINA OP. BICO PVC Nº 41 | E21: =_xlfn.XLOOKUP(B21,ESTOQUE!B:B,ESTOQUE!G:G) -> PAR | F21: 21 | G21: 62.7 | H21: =F21*G21 -> 1316.7 | K21: Ajuste de estoque conforme inventário
A22: 45929 | B22: 40 | C22: =IF(ISBLANK($B22),"",IFERROR(VLOOKUP($B22,ESTOQUE!$B$2:$D$97168,2,FALSE),"Produto não cadastrado")) -> CONSUMO | D22: =IF(ISBLANK($B22),"",IFERROR(VLOOKUP($B22,ESTOQUE!$B$2:$M$997973,3,FALSE),"Produto não cadastrado")) -> BOTINA OP. BICO PVC Nº 42 | E22: =_xlfn.XLOOKUP(B22,ESTOQUE!B:B,ESTOQUE!G:G) -> PAR | F22: 15 | G22: 62.7 | H22: =F22*G22 -> 940.5 | K22: Ajuste de estoque conforme inventário
A23: 45929 | B23: 41 | C23: =IF(ISBLANK($B23),"",IFERROR(VLOOKUP($B23,ESTOQUE!$B$2:$D$97168,2,FALSE),"Produto não cadastrado")) -> CONSUMO | D23: =IF(ISBLANK($B23),"",IFERROR(VLOOKUP($B23,ESTOQUE!$B$2:$M$997973,3,FALSE),"Produto não cadastrado")) -> BOTINA OP. BICO PVC Nº 43 | E23: =_xlfn.XLOOKUP(B23,ESTOQUE!B:B,ESTOQUE!G:G) -> PAR | F23: 13 | G23: 62.7 | H23: =F23*G23 -> 815.1 | K23: Ajuste de estoque conforme inventário
... A45: 45929 | B45: 71 | C45: =IF(ISBLANK($B45),"",IFERROR(VLOOKUP($B45,ESTOQUE!$B$2:$D$97168,2,FALSE),"Produto não cadastrado")) -> CONSUMO | D45: =IF(ISBLANK($B45),"",IFERROR(VLOOKUP($B45,ESTOQUE!$B$2:$M$997973,3,FALSE),"Produto não cadastrado")) -> CAMISA LARANJA OP. C/ FAIXA REFLETIVA TAM: XG | E45: =_xlfn.XLOOKUP(B45,ESTOQUE!B:B,ESTOQUE!G:G) -> UND | F45: 44 | G45: 74.4 | H45: =F45*G45 -> 3273.6 | K45: Ajuste de estoque conforme inventário
A46: 45929 | B46: 200 | C46: =IF(ISBLANK($B46),"",IFERROR(VLOOKUP($B46,ESTOQUE!$B$2:$D$97168,2,FALSE),"Produto não cadastrado")) -> CONSUMO | D46: CAMISA LARANJA OP. C/ FAIXA REFLETIVA TAM XGG | E46: =_xlfn.XLOOKUP(B46,ESTOQUE!B:B,ESTOQUE!G:G) -> UND | F46: 1 | G46: 74.4 | H46: =F46*G46 -> 74.4 | K46: Ajuste de estoque conforme inventário
A47: 45929 | B47: 72 | C47: =IF(ISBLANK($B47),"",IFERROR(VLOOKUP($B47,ESTOQUE!$B$2:$D$97168,2,FALSE),"Produto não cadastrado")) -> CONSUMO | D47: =IF(ISBLANK($B47),"",IFERROR(VLOOKUP($B47,ESTOQUE!$B$2:$M$997973,3,FALSE),"Produto não cadastrado")) -> CAPA DE CHUVA G | E47: =_xlfn.XLOOKUP(B47,ESTOQUE!B:B,ESTOQUE!G:G) -> UND | F47: 8 | G47: 17.9 | H47: =F47*G47 -> 143.2 | K47: Ajuste de estoque conforme inventário
A48: 45929 | B48: 73 | C48: =IF(ISBLANK($B48),"",IFERROR(VLOOKUP($B48,ESTOQUE!$B$2:$D$97168,2,FALSE),"Produto não cadastrado")) -> CONSUMO | D48: =IF(ISBLANK($B48),"",IFERROR(VLOOKUP($B48,ESTOQUE!$B$2:$M$997973,3,FALSE),"Produto não cadastrado")) -> CAPA DE CHUVA GG | E48: =_xlfn.XLOOKUP(B48,ESTOQUE!B:B,ESTOQUE!G:G) -> UND | F48: 87 | G48: 17.9 | H48: =F48*G48 -> 1557.3 | K48: Ajuste de estoque conforme inventário
A49: 45929 | B49: 75 | C49: =IF(ISBLANK($B49),"",IFERROR(VLOOKUP($B49,ESTOQUE!$B$2:$D$97168,2,FALSE),"Produto não cadastrado")) -> CONSUMO | D49: =IF(ISBLANK($B49),"",IFERROR(VLOOKUP($B49,ESTOQUE!$B$2:$M$997973,3,FALSE),"Produto não cadastrado")) -> CAPACETE CAMPER AZUL ESCURO | E49: =_xlfn.XLOOKUP(B49,ESTOQUE!B:B,ESTOQUE!G:G) -> UND | F49: 14 | G49: 16.97 | H49: =F49*G49 -> 237.58 | K49: Ajuste de estoque conforme inventário
A50: 45929 | B50: 76 | C50: =IF(ISBLANK($B50),"",IFERROR(VLOOKUP($B50,ESTOQUE!$B$2:$D$97168,2,FALSE),"Produto não cadastrado")) -> CONSUMO | D50: =IF(ISBLANK($B50),"",IFERROR(VLOOKUP($B50,ESTOQUE!$B$2:$M$997973,3,FALSE),"Produto não cadastrado")) -> CAPACETE CAMPER BRANCO | E50: =_xlfn.XLOOKUP(B50,ESTOQUE!B:B,ESTOQUE!G:G) -> UND | F50: 6 | G50: 16.97 | H50: =F50*G50 -> 101.82 | K50: Ajuste de estoque conforme inventário
A51: 45929 | B51: 77 | C51: =IF(ISBLANK($B51),"",IFERROR(VLOOKUP($B51,ESTOQUE!$B$2:$D$97168,2,FALSE),"Produto não cadastrado")) -> CONSUMO | D51: =IF(ISBLANK($B51),"",IFERROR(VLOOKUP($B51,ESTOQUE!$B$2:$M$997973,3,FALSE),"Produto não cadastrado")) -> CAPACETE CAMPER CINZA | E51: =_xlfn.XLOOKUP(B51,ESTOQUE!B:B,ESTOQUE!G:G) -> UND | F51: 10 | G51: 15.97 | H51: =F51*G51 -> 159.7 | K51: Ajuste de estoque conforme inventário
A52: 45929 | B52: 177 | C52: =IF(ISBLANK($B52),"",IFERROR(VLOOKUP($B52,ESTOQUE!$B$2:$D$97168,2,FALSE),"Produto não cadastrado")) -> CONSUMO | D52: =IF(ISBLANK($B52),"",IFERROR(VLOOKUP($B52,ESTOQUE!$B$2:$M$997973,3,FALSE),"Produto não cadastrado")) -> CAPACETE GENISIS AMARELO | E52: =_xlfn.XLOOKUP(B52,ESTOQUE!B:B,ESTOQUE!G:G) -> UND | F52: 19 | G52: 15.97 | H52: =F52*G52 -> 303.43 | K52: Ajuste de estoque conforme inventário
A53: 45929 | B53: 180 | C53: =IF(ISBLANK($B53),"",IFERROR(VLOOKUP($B53,ESTOQUE!$B$2:$D$97168,2,FALSE),"Produto não cadastrado")) -> CONSUMO | D53: =IF(ISBLANK($B53),"",IFERROR(VLOOKUP($B53,ESTOQUE!$B$2:$M$997973,3,FALSE),"Produto não cadastrado")) -> CAPACETE GENISIS MARRON | E53: =_xlfn.XLOOKUP(B53,ESTOQUE!B:B,ESTOQUE!G:G) -> UND | F53: 15 | G53: 15.97 | H53: =F53*G53 -> 239.55 | K53: Ajuste de estoque conforme inventário
A54: 45929 | B54: 181 | C54: =IF(ISBLANK($B54),"",IFERROR(VLOOKUP($B54,ESTOQUE!$B$2:$D$97168,2,FALSE),"Produto não cadastrado")) -> CONSUMO | D54: =IF(ISBLANK($B54),"",IFERROR(VLOOKUP($B54,ESTOQUE!$B$2:$M$997973,3,FALSE),"Produto não cadastrado")) -> CAPACETE GENISIS VERDE | E54: =_xlfn.XLOOKUP(B54,ESTOQUE!B:B,ESTOQUE!G:G) -> UND | F54: 20 | G54: 15.97 | H54: =F54*G54 -> 319.4 | K54: Ajuste de estoque conforme inventário
A55: 45929 | B55: 178 | C55: =IF(ISBLANK($B55),"",IFERROR(VLOOKUP($B55,ESTOQUE!$B$2:$D$97168,2,FALSE),"Produto não cadastrado")) -> CONSUMO | D55: =IF(ISBLANK($B55),"",IFERROR(VLOOKUP($B55,ESTOQUE!$B$2:$M$997973,3,FALSE),"Produto não cadastrado")) -> CAPACETE GENISIS VERMELHO | E55: =_xlfn.XLOOKUP(B55,ESTOQUE!B:B,ESTOQUE!G:G) -> UND | F55: 26 | G55: 15.97 | H55: =F55*G55 -> 415.22 | K55: Ajuste de estoque conforme inventário
A56: 45929 | B56: 87 | C56: =IF(ISBLANK($B56),"",IFERROR(VLOOKUP($B56,ESTOQUE!$B$2:$D$97168,2,FALSE),"Produto não cadastrado")) -> CONSUMO | D56: =IF(ISBLANK($B56),"",IFERROR(VLOOKUP($B56,ESTOQUE!$B$2:$M$997973,3,FALSE),"Produto não cadastrado")) -> CAPACETE PLASTCOR AMARELO | E56: =_xlfn.XLOOKUP(B56,ESTOQUE!B:B,ESTOQUE!G:G) -> UND | F56: 5 | G56: 15.16 | H56: =F56*G56 -> 75.8 | K56: Ajuste de estoque conforme inventário
A57: 45929 | B57: 91 | C57: =IF(ISBLANK($B57),"",IFERROR(VLOOKUP($B57,ESTOQUE!$B$2:$D$97168,2,FALSE),"Produto não cadastrado")) -> CONSUMO | D57: =IF(ISBLANK($B57),"",IFERROR(VLOOKUP($B57,ESTOQUE!$B$2:$M$997973,3,FALSE),"Produto não cadastrado")) -> CAPACETE PLASTCOR ROXO | E57: =_xlfn.XLOOKUP(B57,ESTOQUE!B:B,ESTOQUE!G:G) -> UND | F57: 8 | G57: 15.16 | H57: =F57*G57 -> 121.28 | K57: Ajuste de estoque conforme inventário
A58: 45929 | B58: 94 | C58: =IF(ISBLANK($B58),"",IFERROR(VLOOKUP($B58,ESTOQUE!$B$2:$D$97168,2,FALSE),"Produto não cadastrado")) -> CONSUMO | D58: =IF(ISBLANK($B58),"",IFERROR(VLOOKUP($B58,ESTOQUE!$B$2:$M$997973,3,FALSE),"Produto não cadastrado")) -> CARNEIRA P/ CAPACETE CAMPER | E58: =_xlfn.XLOOKUP(B58,ESTOQUE!B:B,ESTOQUE!G:G) -> UND | F58: 100 | G58: 15.16 | H58: =F58*G58 -> 1516 | K58: Ajuste de estoque conforme inventário
... A62: 45929 | B62: 188 | C62: =IF(ISBLANK($B62),"",IFERROR(VLOOKUP($B62,ESTOQUE!$B$2:$D$97168,2,FALSE),"Produto não cadastrado")) -> CONSUMO | D62: =IF(ISBLANK($B62),"",IFERROR(VLOOKUP($B62,ESTOQUE!$B$2:$M$997973,3,FALSE),"Produto não cadastrado")) -> COLETE REFLETIVO LARANJA XG | E62: =_xlfn.XLOOKUP(B62,ESTOQUE!B:B,ESTOQUE!G:G) -> UND | F62: 5 | G62: 19 | H62: =F62*G62 -> 95 | K62: Ajuste de estoque conforme inventário
A63: 45929 | B63: 98 | C63: =IF(ISBLANK($B63),"",IFERROR(VLOOKUP($B63,ESTOQUE!$B$2:$D$97168,2,FALSE),"Produto não cadastrado")) -> CONSUMO | D63: COLETE REFLETIVO LARANJA XGG | E63: =_xlfn.XLOOKUP(B63,ESTOQUE!B:B,ESTOQUE!G:G) -> UND | F63: 87 | G63: 19 | H63: =F63*G63 -> 1653 | K63: Ajuste de estoque conforme inventário
A64: 45929 | B64: 156 | C64: =IF(ISBLANK($B64),"",IFERROR(VLOOKUP($B64,ESTOQUE!$B$2:$D$97168,2,FALSE),"Produto não cadastrado")) -> CONSUMO | D64: =IF(ISBLANK($B64),"",IFERROR(VLOOKUP($B64,ESTOQUE!$B$2:$M$997973,3,FALSE),"Produto não cadastrado")) -> CONJUNTO NR 10 AZUL CLASSE 2 TAM G | E64: =_xlfn.XLOOKUP(B64,ESTOQUE!B:B,ESTOQUE!G:G) -> CONJ | F64: 5 | G64: 375.9 | H64: =F64*G64 -> 1879.5 | K64: Ajuste de estoque conforme inventário
...

Sheet ESTOQUE
B1: COD | C1: GRUPO | D1: DESCRIÇÃO DO ITEM | E1: CA | F1: VALIDADE CA | G1: UNID | H1: EST.MIN | I1: EST.MAX | J1: EST. ATUAL | K1: COMPRA | L1: OBSERVAÇÃO | N1: DESCRIÇÃO | O1: ENTRADA | P1: SAÍDA | Q1: SALDO | R1: STATUS | S1: VALOR UNIT. | T1: VALOR TOTAL DO ESTOQUE | U1: VALOR TOTAL DA SAÍDA
B2: 1 | C2: CONSUMO | D2: ABAFADOR DE RUIDOS TIPO CONCHA | E2: 10468 | F2: 09/08/2027 | G2: UND | H2: 80 | I2: 300 | J2: =Q2 -> 25 | K2: =I2-J2 -> 275 | L2: =IF(J2<H2,"ESTOQUE BAIXO",IF(J2>I2,"ESTOQUE ALTO",IF(J2>=H2,"ESTOQUE NORMAL",))) -> ESTOQUE BAIXO | M2: 1 | N2: =D2 -> ABAFADOR DE RUIDOS TIPO CONCHA | O2: =SUMIFS(ENTRADA!$F:$F,ENTRADA!$B:$B,ESTOQUE!$B2) -> 47 | P2: =SUMIFS(SAIDA!$F:$F,SAIDA!$B:$B,ESTOQUE!$B2) -> 22 | Q2: =O2-P2 -> 25 | R2: =Q2=#REF! -> #REF! | S2: =IFERROR(SUMIFS(ENTRADA!$H:$H,ENTRADA!$B:$B,ESTOQUE!$B2)/O2,0) -> 0 | T2: =Q2*S2 -> 0 | U2: =P2*S2 -> 0
B3: 158 | C3: CONSUMO | D3: AVENTAL DE PVC | E3: 47042 | F3: 46373 | G3: UND | H3: 100 | I3: 300 | J3: =Q3 -> 0 | K3: =I3-J3 -> 300 | L3: =IF(J3<H3,"ESTOQUE BAIXO",IF(J3>I3,"ESTOQUE ALTO",IF(J3>=H3,"ESTOQUE NORMAL",))) -> ESTOQUE BAIXO | M3: 3 | N3: =D3 -> AVENTAL DE PVC | O3: =SUMIFS(ENTRADA!$F:$F,ENTRADA!$B:$B,ESTOQUE!$B3) -> 0 | P3: =SUMIFS(SAIDA!$F:$F,SAIDA!$B:$B,ESTOQUE!$B3) -> 0 | Q3: =O3-P3 -> 0 | R3: =Q3=#REF! -> #REF! | S3: =IFERROR(SUMIFS(ENTRADA!$H:$H,ENTRADA!$B:$B,ESTOQUE!$B3)/O3,0) -> 0 | T3: =Q3*S3 -> 0 | U3: =P3*S3 -> 0
B4: 190 | C4: CONSUMO | D4: AVENTAL DE RASPA TAM 120X60 | E4: N/A | F4: N/A | G4: UND | H4: 50 | I4: 100 | J4: =Q4 -> 144 | K4: =I4-J4 -> -44 | L4: =IF(J4<H4,"ESTOQUE BAIXO",IF(J4>I4,"ESTOQUE ALTO",IF(J4>=H4,"ESTOQUE NORMAL",))) -> ESTOQUE ALTO | N4: =D4 -> AVENTAL DE RASPA TAM 120X60 | O4: =SUMIFS(ENTRADA!$F:$F,ENTRADA!$B:$B,ESTOQUE!$B4) -> 231 | P4: =SUMIFS(SAIDA!$F:$F,SAIDA!$B:$B,ESTOQUE!$B4) -> 87 | Q4: =O4-P4 -> 144 | R4: =Q4=#REF! -> #REF! | S4: =IFERROR(SUMIFS(ENTRADA!$H:$H,ENTRADA!$B:$B,ESTOQUE!$B4)/O4,0) -> 0 | T4: =Q4*S4 -> 0 | U4: =P4*S4 -> 0
B5: 2 | C5: CONSUMO | D5: AVENTAL DE RASPA TAM 1X60MT | E5: 42248 | F5: 47065 | G5: UND | H5: 60 | I5: 100 | J5: 16 | K5: =I5-J5 -> 84 | L5: =IF(J5<H5,"ESTOQUE BAIXO",IF(J5>I5,"ESTOQUE ALTO",IF(J5>=H5,"ESTOQUE NORMAL",))) -> ESTOQUE BAIXO | M5: 6 | N5: =D5 -> AVENTAL DE RASPA TAM 1X60MT | O5: =SUMIFS(ENTRADA!$F:$F,ENTRADA!$B:$B,ESTOQUE!$B5) -> 20 | P5: =SUMIFS(SAIDA!$F:$F,SAIDA!$B:$B,ESTOQUE!$B5) -> 76 | Q5: =O5-P5 -> -56 | R5: =Q5=#REF! -> #REF! | S5: =IFERROR(SUMIFS(ENTRADA!$H:$H,ENTRADA!$B:$B,ESTOQUE!$B5)/O5,0) -> 49 | T5: =Q5*S5 -> -2744 | U5: =P5*S5 -> 3724
B6: 3 | C6: CONSUMO | D6: AVENTAL IMPERMEAVEL | E6: 33301 | F6: 46944 | G6: UND | H6: 50 | I6: 100 | J6: =Q6 -> 0 | K6: =I6-J6 -> 100 | L6: =IF(J6<H6,"ESTOQUE BAIXO",IF(J6>I6,"ESTOQUE ALTO",IF(J6>=H6,"ESTOQUE NORMAL",))) -> ESTOQUE BAIXO | M6: 7 | N6: =D6 -> AVENTAL IMPERMEAVEL | O6: =SUMIFS(ENTRADA!$F:$F,ENTRADA!$B:$B,ESTOQUE!$B6) -> 0 | P6: =SUMIFS(SAIDA!$F:$F,SAIDA!$B:$B,ESTOQUE!$B6) -> 0 | Q6: =O6-P6 -> 0 | R6: =Q6=#REF! -> #REF! | S6: =IFERROR(SUMIFS(ENTRADA!$H:$H,ENTRADA!$B:$B,ESTOQUE!$B6)/O6,0) -> 0 | T6: =Q6*S6 -> 0 | U6: =P6*S6 -> 0
B7: 228 | C7: CONSUMO | D7: BALACLAVA | E7: N/A | F7: N/A | G7: UND | H7: 1 | I7: 1000 | J7: =Q7 -> 137 | K7: =I7-J7 -> 863 | L7: =IF(J7<H7,"ESTOQUE BAIXO",IF(J7>I7,"ESTOQUE ALTO",IF(J7>H7,"ESTOQUE NORMAL",))) -> ESTOQUE NORMAL | M7: 8 | N7: =D7 -> BALACLAVA | O7: =SUMIFS(ENTRADA!$F:$F,ENTRADA!$B:$B,ESTOQUE!$B7) -> 838 | P7: =SUMIFS(SAIDA!$F:$F,SAIDA!$B:$B,ESTOQUE!$B7) -> 701 | Q7: =O7-P7 -> 137 | R7: =Q7=#REF! -> #REF! | S7: =IFERROR(SUMIFS(ENTRADA!$H:$H,ENTRADA!$B:$B,ESTOQUE!$B7)/O7,0) -> 5.6384248 | T7: =Q7*S7 -> 772.4642 | U7: =P7*S7 -> 3952.5358
B8: 4 | C8: CONSUMO | D8: BLUSÃO DE RASPA MANGA LONGA | E8: 42495 | F8: 45307 | G8: UND | H8: 20 | I8: 50 | J8: =Q8 -> 0 | K8: =I8-J8 -> 50 | L8: =IF(J8<H8,"ESTOQUE BAIXO",IF(J8>I8,"ESTOQUE ALTO",IF(J8>=H8,"ESTOQUE NORMAL",))) -> ESTOQUE BAIXO | N8: =D8 -> BLUSÃO DE RASPA MANGA LONGA | O8: =SUMIFS(ENTRADA!$F:$F,ENTRADA!$B:$B,ESTOQUE!$B8) -> 26 | P8: =SUMIFS(SAIDA!$F:$F,SAIDA!$B:$B,ESTOQUE!$B8) -> 26 | Q8: =O8-P8 -> 0 | R8: =Q8=#REF! -> #REF! | S8: =IFERROR(SUMIFS(ENTRADA!$H:$H,ENTRADA!$B:$B,ESTOQUE!$B8)/O8,0) -> 3.5315385 | T8: =Q8*S8 -> 0 | U8: =P8*S8 -> 91.82
B9: 268 | C9: CONSUMO | D9: BOTA PVC CANO CURTO N 39 | E9: 36025 | F9: 47317 | G9: PAR | H9: 5 | I9: 20 | J9: =Q9 -> 17 | K9: =I9-J9 -> 3 | L9: =IF(J9<H9,"ESTOQUE BAIXO",IF(J9>I9,"ESTOQUE ALTO",IF(J9>H9,"ESTOQUE NORMAL",))) -> ESTOQUE NORMAL | N9: =D9 -> BOTA PVC CANO CURTO N 39 | O9: =SUMIFS(ENTRADA!$F:$F,ENTRADA!$B:$B,ESTOQUE!$B9) -> 19 | P9: =SUMIFS(SAIDA!$F:$F,SAIDA!$B:$B,ESTOQUE!$B9) -> 2 | Q9: =O9-P9 -> 17 | R9: =Q9=#REF! -> #REF! | S9: =IFERROR(SUMIFS(ENTRADA!$H:$H,ENTRADA!$B:$B,ESTOQUE!$B9)/O9,0) -> 0 | T9: =Q9*S9 -> 0 | U9: =P9*S9 -> 0
B10: 171 | C10: CONSUMO | D10: BOTA PVC CANO CURTO Nº 40 | E10: 36025 | F10: 47317 | G10: PAR | H10: 5 | I10: 20 | J10: =Q10 -> 15 | K10: =I10-J10 -> 5 | L10: =IF(J10<H10,"ESTOQUE BAIXO",IF(J10>I10,"ESTOQUE ALTO",IF(J10>=H10,"ESTOQUE NORMAL",))) -> ESTOQUE NORMAL | N10: =D10 -> BOTA PVC CANO CURTO Nº 40 | O10: =SUMIFS(ENTRADA!$F:$F,ENTRADA!$B:$B,ESTOQUE!$B10) -> 27 | P10: =SUMIFS(SAIDA!$F:$F,SAIDA!$B:$B,ESTOQUE!$B10) -> 12 | Q10: =O10-P10 -> 15 | R10: =Q10=#REF! -> #REF! | S10: =IFERROR(SUMIFS(ENTRADA!$H:$H,ENTRADA!$B:$B,ESTOQUE!$B10)/O10,0) -> 0 | T10: =Q10*S10 -> 0 | U10: =P10*S10 -> 0
B11: 172 | C11: CONSUMO | D11: BOTA PVC CANO CURTO Nº 41 | E11: 36025 | F11: 47317 | G11: PAR | H11: 5 | I11: 20 | J11: =Q11 -> 1 | K11: =I11-J11 -> 19 | L11: =IF(J11<H11,"ESTOQUE BAIXO",IF(J11>I11,"ESTOQUE ALTO",IF(J11>=H11,"ESTOQUE NORMAL",))) -> ESTOQUE BAIXO | N11: =D11 -> BOTA PVC CANO CURTO Nº 41 | O11: =SUMIFS(ENTRADA!$F:$F,ENTRADA!$B:$B,ESTOQUE!$B11) -> 9 | P11: =SUMIFS(SAIDA!$F:$F,SAIDA!$B:$B,ESTOQUE!$B11) -> 8 | Q11: =O11-P11 -> 1 | R11: =Q11=#REF! -> #REF! | S11: =IFERROR(SUMIFS(ENTRADA!$H:$H,ENTRADA!$B:$B,ESTOQUE!$B11)/O11,0) -> 0 | T11: =Q11*S11 -> 0 | U11: =P11*S11 -> 0
B12: 173 | C12: CONSUMO | D12: BOTA PVC CANO CURTO Nº 42 | E12: 36025 | F12: 47317 | G12: PAR | H12: 5 | I12: 20 | J12: =Q12 -> 0 | K12: =I12-J12 -> 20 | L12: =IF(J12<H12,"ESTOQUE BAIXO",IF(J12>I12,"ESTOQUE ALTO",IF(J12>=H12,"ESTOQUE NORMAL",))) -> ESTOQUE BAIXO | N12: =D12 -> BOTA PVC CANO CURTO Nº 42 | O12: =SUMIFS(ENTRADA!$F:$F,ENTRADA!$B:$B,ESTOQUE!$B12) -> 10 | P12: =SUMIFS(SAIDA!$F:$F,SAIDA!$B:$B,ESTOQUE!$B12) -> 10 | Q12: =O12-P12 -> 0 | R12: =Q12=#REF! -> #REF! | S12: =IFERROR(SUMIFS(ENTRADA!$H:$H,ENTRADA!$B:$B,ESTOQUE!$B12)/O12,0) -> 0 | T12: =Q12*S12 -> 0 | U12: =P12*S12 -> 0
B13: 174 | C13: CONSUMO | D13: BOTA PVC CANO CURTO Nº 43 | E13: 36025 | F13: 47317 | G13: PAR | H13: 5 | I13: 20 | J13: =Q13 -> 9 | K13: =I13-J13 -> 11 | L13: =IF(J13<H13,"ESTOQUE BAIXO",IF(J13>I13,"ESTOQUE ALTO",IF(J13>=H13,"ESTOQUE NORMAL",))) -> ESTOQUE NORMAL | N13: =D13 -> BOTA PVC CANO CURTO Nº 43 | O13: =SUMIFS(ENTRADA!$F:$F,ENTRADA!$B:$B,ESTOQUE!$B13) -> 19 | P13: =SUMIFS(SAIDA!$F:$F,SAIDA!$B:$B,ESTOQUE!$B13) -> 10 | Q13: =O13-P13 -> 9 | R13: =Q13=#REF! -> #REF! | S13: =IFERROR(SUMIFS(ENTRADA!$H:$H,ENTRADA!$B:$B,ESTOQUE!$B13)/O13,0) -> 0 | T13: =Q13*S13 -> 0 | U13: =P13*S13 -> 0
B14: 5 | C14: CONSUMO | D14: BOTA PVC CANO LONGO Nº 37 | E14: 39184 | F14: 47394 | G14: PAR | H14: 10 | I14: 100 | J14: =Q14 -> 0 | K14: =I14-J14 -> 100 | L14: =IF(J14<H14,"ESTOQUE BAIXO",IF(J14>I14,"ESTOQUE ALTO",IF(J14>=H14,"ESTOQUE NORMAL",))) -> ESTOQUE BAIXO | N14: =D14 -> BOTA PVC CANO LONGO Nº 37 | O14: =SUMIFS(ENTRADA!$F:$F,ENTRADA!$B:$B,ESTOQUE!$B14) -> 0 | P14: =SUMIFS(SAIDA!$F:$F,SAIDA!$B:$B,ESTOQUE!$B14) -> 0 | Q14: =O14-P14 -> 0 | R14: =Q14=#REF! -> #REF! | S14: =IFERROR(SUMIFS(ENTRADA!$H:$H,ENTRADA!$B:$B,ESTOQUE!$B14)/O14,0) -> 0 | T14: =Q14*S14 -> 0 | U14: =P14*S14 -> 0
B15: 6 | C15: CONSUMO | D15: BOTA PVC CANO LONGO Nº 38 | E15: 39184 | F15: 47394 | G15: PAR | H15: 30 | I15: 100 | J15: =Q15 -> 4 | K15: =I15-J15 -> 96 | L15: =IF(J15<H15,"ESTOQUE BAIXO",IF(J15>I15,"ESTOQUE ALTO",IF(J15>=H15,"ESTOQUE NORMAL",))) -> ESTOQUE BAIXO | N15: =D15 -> BOTA PVC CANO LONGO Nº 38 | O15: =SUMIFS(ENTRADA!$F:$F,ENTRADA!$B:$B,ESTOQUE!$B15) -> 11 | P15: =SUMIFS(SAIDA!$F:$F,SAIDA!$B:$B,ESTOQUE!$B15) -> 7 | Q15: =O15-P15 -> 4 | R15: =Q15=#REF! -> #REF! | S15: =IFERROR(SUMIFS(ENTRADA!$H:$H,ENTRADA!$B:$B,ESTOQUE!$B15)/O15,0) -> 0 | T15: =Q15*S15 -> 0 | U15: =P15*S15 -> 0
B16: 7 | C16: CONSUMO | D16: BOTA PVC CANO LONGO Nº 39 | E16: 39184 | F16: 47394 | G16: PAR | H16: 100 | I16: 250 | J16: =Q16 -> 0 | K16: =I16-J16 -> 250 | L16: =IF(J16<H16,"ESTOQUE BAIXO",IF(J16>I16,"ESTOQUE ALTO",IF(J16>=H16,"ESTOQUE NORMAL",))) -> ESTOQUE BAIXO | M16: 10 | N16: =D16 -> BOTA PVC CANO LONGO Nº 39 | O16: =SUMIFS(ENTRADA!$F:$F,ENTRADA!$B:$B,ESTOQUE!$B16) -> 21 | P16: =SUMIFS(SAIDA!$F:$F,SAIDA!$B:$B,ESTOQUE!$B16) -> 21 | Q16: =O16-P16 -> 0 | R16: =Q16=#REF! -> #REF! | S16: =IFERROR(SUMIFS(ENTRADA!$H:$H,ENTRADA!$B:$B,ESTOQUE!$B16)/O16,0) -> 10.72381 | T16: =Q16*S16 -> 0 | U16: =P16*S16 -> 225.2
B17: 8 | C17: CONSUMO | D17: BOTA PVC CANO LONGO Nº 40 | E17: 39184 | F17: 47394 | G17: PAR | H17: 100 | I17: 250 | J17: =Q17 -> 0 | K17: =I17-J17 -> 250 | L17: =IF(J17<H17,"ESTOQUE BAIXO",IF(J17>I17,"ESTOQUE ALTO",IF(J17>=H17,"ESTOQUE NORMAL",))) -> ESTOQUE BAIXO | M17: 11 | N17: =D17 -> BOTA PVC CANO LONGO Nº 40 | O17: =SUMIFS(ENTRADA!$F:$F,ENTRADA!$B:$B,ESTOQUE!$B17) -> 15 | P17: =SUMIFS(SAIDA!$F:$F,SAIDA!$B:$B,ESTOQUE!$B17) -> 15 | Q17: =O17-P17 -> 0 | R17: =Q17=#REF! -> #REF! | S17: =IFERROR(SUMIFS(ENTRADA!$H:$H,ENTRADA!$B:$B,ESTOQUE!$B17)/O17,0) -> 0 | T17: =Q17*S17 -> 0 | U17: =P17*S17 -> 0
B18: 9 | C18: CONSUMO | D18: BOTA PVC CANO LONGO Nº 41 | E18: 39184 | F18: 47394 | G18: PAR | H18: 100 | I18: 250 | J18: =Q18 -> 0 | K18: =I18-J18 -> 250 | L18: =IF(J18<H18,"ESTOQUE BAIXO",IF(J18>I18,"ESTOQUE ALTO",IF(J18>=H18,"ESTOQUE NORMAL",))) -> ESTOQUE BAIXO | M18: 14 | N18: =D18 -> BOTA PVC CANO LONGO Nº 41 | O18: =SUMIFS(ENTRADA!$F:$F,ENTRADA!$B:$B,ESTOQUE!$B18) -> 16 | P18: =SUMIFS(SAIDA!$F:$F,SAIDA!$B:$B,ESTOQUE!$B18) -> 16 | Q18: =O18-P18 -> 0 | R18: =Q18=#REF! -> #REF! | S18: =IFERROR(SUMIFS(ENTRADA!$H:$H,ENTRADA!$B:$B,ESTOQUE!$B18)/O18,0) -> 0 | T18: =Q18*S18 -> 0 | U18: =P18*S18 -> 0
B19: 10 | C19: CONSUMO | D19: BOTA PVC CANO LONGO Nº 42 | E19: 39184 | F19: 47394 | G19: PAR | H19: 100 | I19: 250 | J19: =Q19 -> 0 | K19: =I19-J19 -> 250 | L19: =IF(J19<H19,"ESTOQUE BAIXO",IF(J19>I19,"ESTOQUE ALTO",IF(J19>=H19,"ESTOQUE NORMAL",))) -> ESTOQUE BAIXO | N19: =D19 -> BOTA PVC CANO LONGO Nº 42 | O19: =SUMIFS(ENTRADA!$F:$F,ENTRADA!$B:$B,ESTOQUE!$B19) -> 65 | P19: =SUMIFS(SAIDA!$F:$F,SAIDA!$B:$B,ESTOQUE!$B19) -> 65 | Q19: =O19-P19 -> 0 | R19: =Q19=#REF! -> #REF! | S19: =IFERROR(SUMIFS(ENTRADA!$H:$H,ENTRADA!$B:$B,ESTOQUE!$B19)/O19,0) -> 6.9292308 | T19: =Q19*S19 -> 0 | U19: =P19*S19 -> 450.4
B20: 11 | C20: CONSUMO | D20: BOTA PVC CANO LONGO Nº 43 | E20: 39184 | F20: 47394 | G20: PAR | H20: 100 | I20: 250 | J20: =Q20 -> 0 | K20: =I20-J20 -> 250 | L20: =IF(J20<H20,"ESTOQUE BAIXO",IF(J20>I20,"ESTOQUE ALTO",IF(J20>=H20,"ESTOQUE NORMAL",))) -> ESTOQUE BAIXO | N20: =D20 -> BOTA PVC CANO LONGO Nº 43 | O20: =SUMIFS(ENTRADA!$F:$F,ENTRADA!$B:$B,ESTOQUE!$B20) -> 33 | P20: =SUMIFS(SAIDA!$F:$F,SAIDA!$B:$B,ESTOQUE!$B20) -> 33 | Q20: =O20-P20 -> 0 | R20: =Q20=#REF! -> #REF! | S20: =IFERROR(SUMIFS(ENTRADA!$H:$H,ENTRADA!$B:$B,ESTOQUE!$B20)/O20,0) -> 20.472727 | T20: =Q20*S20 -> 0 | U20: =P20*S20 -> 675.6
B21: 12 | C21: CONSUMO | D21: BOTA PVC CANO LONGO Nº 44 | E21: 39184 | F21: 47394 | G21: PAR | H21: 100 | I21: 250 | J21: =Q21 -> 0 | K21: =I21-J21 -> 250 | L21: =IF(J21<H21,"ESTOQUE BAIXO",IF(J21>I21,"ESTOQUE ALTO",IF(J21>=H21,"ESTOQUE NORMAL",))) -> ESTOQUE BAIXO | N21: =D21 -> BOTA PVC CANO LONGO Nº 44 | O21: =SUMIFS(ENTRADA!$F:$F,ENTRADA!$B:$B,ESTOQUE!$B21) -> 16 | P21: =SUMIFS(SAIDA!$F:$F,SAIDA!$B:$B,ESTOQUE!$B21) -> 16 | Q21: =O21-P21 -> 0 | R21: =Q21=#REF! -> #REF! | S21: =IFERROR(SUMIFS(ENTRADA!$H:$H,ENTRADA!$B:$B,ESTOQUE!$B21)/O21,0) -> 3.51875 | T21: =Q21*S21 -> 0 | U21: =P21*S21 -> 56.3
B22: 13 | C22: CONSUMO | D22: BOTA PVC CANO LONGO Nº 45 | E22: 39184 | F22: 47394 | G22: PAR | H22: 50 | I22: 250 | J22: =Q22 -> 6 | K22: =I22-J22 -> 244 | L22: =IF(J22<H22,"ESTOQUE BAIXO",IF(J22>I22,"ESTOQUE ALTO",IF(J22>=H22,"ESTOQUE NORMAL",))) -> ESTOQUE BAIXO | N22: =D22 -> BOTA PVC CANO LONGO Nº 45 | O22: =SUMIFS(ENTRADA!$F:$F,ENTRADA!$B:$B,ESTOQUE!$B22) -> 26 | P22: =SUMIFS(SAIDA!$F:$F,SAIDA!$B:$B,ESTOQUE!$B22) -> 20 | Q22: =O22-P22 -> 6 | R22: =Q22=#REF! -> #REF! | S22: =IFERROR(SUMIFS(ENTRADA!$H:$H,ENTRADA!$B:$B,ESTOQUE!$B22)/O22,0) -> 21.653846 | T22: =Q22*S22 -> 129.92308 | U22: =P22*S22 -> 433.07692
B23: 14 | C23: CONSUMO | D23: BOTA PVC CANO LONGO Nº 46 | E23: 39184 | F23: 47394 | G23: PAR | H23: 20 | I23: 250 | J23: =Q23 -> 10 | K23: =I23-J23 -> 240 | L23: =IF(J23<H23,"ESTOQUE BAIXO",IF(J23>I23,"ESTOQUE ALTO",IF(J23>=H23,"ESTOQUE NORMAL",))) -> ESTOQUE BAIXO | N23: =D23 -> BOTA PVC CANO LONGO Nº 46 | O23: =SUMIFS(ENTRADA!$F:$F,ENTRADA!$B:$B,ESTOQUE!$B23) -> 13 | P23: =SUMIFS(SAIDA!$F:$F,SAIDA!$B:$B,ESTOQUE!$B23) -> 3 | Q23: =O23-P23 -> 10 | R23: =Q23=#REF! -> #REF! | S23: =IFERROR(SUMIFS(ENTRADA!$H:$H,ENTRADA!$B:$B,ESTOQUE!$B23)/O23,0) -> 4.3307692 | T23: =Q23*S23 -> 43.307692 | U23: =P23*S23 -> 12.992308
B24: 165 | C24: CONSUMO | D24: BOTA PVC CANO LONGO Nº 47 | E24: 39184 | F24: 47394 | G24: PAR | H24: 10 | I24: 250 | J24: =Q24 -> 0 | K24: =I24-J24 -> 250 | L24: =IF(J24<H24,"ESTOQUE BAIXO",IF(J24>I24,"ESTOQUE ALTO",IF(J24>=H24,"ESTOQUE NORMAL",))) -> ESTOQUE BAIXO | N24: =D24 -> BOTA PVC CANO LONGO Nº 47 | O24: =SUMIFS(ENTRADA!$F:$F,ENTRADA!$B:$B,ESTOQUE!$B24) -> 0 | P24: =SUMIFS(SAIDA!$F:$F,SAIDA!$B:$B,ESTOQUE!$B24) -> 0 | Q24: =O24-P24 -> 0 | R24: =Q24=#REF! -> #REF! | S24: =IFERROR(SUMIFS(ENTRADA!$H:$H,ENTRADA!$B:$B,ESTOQUE!$B24)/O24,0) -> 0 | T24: =Q24*S24 -> 0 | U24: =P24*S24 -> 0
B25: 15 | C25: CONSUMO | D25: BOTA PVC CANO LONGO Nº 48 | E25: 39184 | F25: 47394 | G25: PAR | H25: 10 | I25: 250 | J25: =Q25 -> 0 | K25: =I25-J25 -> 250 | L25: =IF(J25<H25,"ESTOQUE BAIXO",IF(J25>I25,"ESTOQUE ALTO",IF(J25>=H25,"ESTOQUE NORMAL",))) -> ESTOQUE BAIXO | N25: =D25 -> BOTA PVC CANO LONGO Nº 48 | O25: =SUMIFS(ENTRADA!$F:$F,ENTRADA!$B:$B,ESTOQUE!$B25) -> 0 | P25: =SUMIFS(SAIDA!$F:$F,SAIDA!$B:$B,ESTOQUE!$B25) -> 0 | Q25: =O25-P25 -> 0 | R25: =Q25=#REF! -> #REF! | S25: =IFERROR(SUMIFS(ENTRADA!$H:$H,ENTRADA!$B:$B,ESTOQUE!$B25)/O25,0) -> 0 | T25: =Q25*S25 -> 0 | U25: =P25*S25 -> 0
B26: 166 | C26: CONSUMO | D26: BOTA PVC CANO MEDIO Nº 34 | E26: 36025 | F26: 47317 | G26: PAR | H26: 10 | I26: 20 | J26: =Q26 -> 0 | K26: =I26-J26 -> 20 | L26: =IF(J26<H26,"ESTOQUE BAIXO",IF(J26>I26,"ESTOQUE ALTO",IF(J26>=H26,"ESTOQUE NORMAL",))) -> ESTOQUE BAIXO | N26: =D26 -> BOTA PVC CANO MEDIO Nº 34 | O26: =SUMIFS(ENTRADA!$F:$F,ENTRADA!$B:$B,ESTOQUE!$B26) -> 0 | P26: =SUMIFS(SAIDA!$F:$F,SAIDA!$B:$B,ESTOQUE!$B26) -> 0 | Q26: =O26-P26 -> 0 | R26: =Q26=#REF! -> #REF! | S26: =IFERROR(SUMIFS(ENTRADA!$H:$H,ENTRADA!$B:$B,ESTOQUE!$B26)/O26,0) -> 0 | T26: =Q26*S26 -> 0 | U26: =P26*S26 -> 0
B27: 167 | C27: CONSUMO | D27: BOTA PVC CANO MEDIO Nº 35 | E27: 36025 | F27: 47317 | G27: PAR | H27: 10 | I27: 20 | J27: =Q27 -> 0 | K27: =I27-J27 -> 20 | L27: =IF(J27<H27,"ESTOQUE BAIXO",IF(J27>I27,"ESTOQUE ALTO",IF(J27>=H27,"ESTOQUE NORMAL",))) -> ESTOQUE BAIXO | M27: 15 | N27: =D27 -> BOTA PVC CANO MEDIO Nº 35 | O27: =SUMIFS(ENTRADA!$F:$F,ENTRADA!$B:$B,ESTOQUE!$B27) -> 0 | P27: =SUMIFS(SAIDA!$F:$F,SAIDA!$B:$B,ESTOQUE!$B27) -> 0 | Q27: =O27-P27 -> 0 | R27: =Q27=#REF! -> #REF! | S27: =IFERROR(SUMIFS(ENTRADA!$H:$H,ENTRADA!$B:$B,ESTOQUE!$B27)/O27,0) -> 0 | T27: =Q27*S27 -> 0 | U27: =P27*S27 -> 0
B28: 168 | C28: CONSUMO | D28: BOTA PVC CANO MEDIO Nº 36 | E28: 36025 | F28: 47317 | G28: PAR | H28: 10 | I28: 20 | J28: =Q28 -> 0 | K28: =I28-J28 -> 20 | L28: =IF(J28<H28,"ESTOQUE BAIXO",IF(J28>I28,"ESTOQUE ALTO",IF(J28>=H28,"ESTOQUE NORMAL",))) -> ESTOQUE BAIXO | M28: 16 | N28: =D28 -> BOTA PVC CANO MEDIO Nº 36 | O28: =SUMIFS(ENTRADA!$F:$F,ENTRADA!$B:$B,ESTOQUE!$B28) -> 6 | P28: =SUMIFS(SAIDA!$F:$F,SAIDA!$B:$B,ESTOQUE!$B28) -> 6 | Q28: =O28-P28 -> 0 | R28: =Q28=#REF! -> #REF! | S28: =IFERROR(SUMIFS(ENTRADA!$H:$H,ENTRADA!$B:$B,ESTOQUE!$B28)/O28,0) -> 0 | T28: =Q28*S28 -> 0 | U28: =P28*S28 -> 0
B29: 16 | C29: CONSUMO | D29: BOTA PVC CANO MEDIO Nº 37 | E29: 36025 | F29: 47317 | G29: PAR | H29: 10 | I29: 20 | J29: =Q29 -> 0 | K29: =I29-J29 -> 20 | L29: =IF(J29<H29,"ESTOQUE BAIXO",IF(J29>I29,"ESTOQUE ALTO",IF(J29>=H29,"ESTOQUE NORMAL",))) -> ESTOQUE BAIXO | M29: 17 | N29: =D29 -> BOTA PVC CANO MEDIO Nº 37 | O29: =SUMIFS(ENTRADA!$F:$F,ENTRADA!$B:$B,ESTOQUE!$B29) -> 5 | P29: =SUMIFS(SAIDA!$F:$F,SAIDA!$B:$B,ESTOQUE!$B29) -> 5 | Q29: =O29-P29 -> 0 | R29: =Q29=#REF! -> #REF! | S29: =IFERROR(SUMIFS(ENTRADA!$H:$H,ENTRADA!$B:$B,ESTOQUE!$B29)/O29,0) -> 34.9 | T29: =Q29*S29 -> 0 | U29: =P29*S29 -> 174.5
B30: 17 | C30: CONSUMO | D30: BOTA PVC CANO MEDIO Nº 38 | E30: 36025 | F30: 47317 | G30: PAR | H30: 20 | I30: 20 | J30: =Q30 -> 0 | K30: =I30-J30 -> 20 | L30: =IF(J30<H30,"ESTOQUE BAIXO",IF(J30>I30,"ESTOQUE ALTO",IF(J30>=H30,"ESTOQUE NORMAL",))) -> ESTOQUE BAIXO | M30: 20 | N30: =D30 -> BOTA PVC CANO MEDIO Nº 38 | O30: =SUMIFS(ENTRADA!$F:$F,ENTRADA!$B:$B,ESTOQUE!$B30) -> 3 | P30: =SUMIFS(SAIDA!$F:$F,SAIDA!$B:$B,ESTOQUE!$B30) -> 3 | Q30: =O30-P30 -> 0 | R30: =Q30=#REF! -> #REF! | S30: =IFERROR(SUMIFS(ENTRADA!$H:$H,ENTRADA!$B:$B,ESTOQUE!$B30)/O30,0) -> 23.266667 | T30: =Q30*S30 -> 0 | U30: =P30*S30 -> 69.8
B31: 18 | C31: CONSUMO | D31: BOTA PVC CANO MEDIO Nº 39 | E31: 36025 | F31: 47317 | G31: PAR | H31: 20 | I31: 20 | J31: =Q31 -> 0 | K31: =I31-J31 -> 20 | L31: =IF(J31<H31,"ESTOQUE BAIXO",IF(J31>I31,"ESTOQUE ALTO",IF(J31>=H31,"ESTOQUE NORMAL",))) -> ESTOQUE BAIXO | M31: 21 | N31: =D31 -> BOTA PVC CANO MEDIO Nº 39 | O31: =SUMIFS(ENTRADA!$F:$F,ENTRADA!$B:$B,ESTOQUE!$B31) -> 1 | P31: =SUMIFS(SAIDA!$F:$F,SAIDA!$B:$B,ESTOQUE!$B31) -> 1 | Q31: =O31-P31 -> 0 | R31: =Q31=#REF! -> #REF! | S31: =IFERROR(SUMIFS(ENTRADA!$H:$H,ENTRADA!$B:$B,ESTOQUE!$B31)/O31,0) -> 0 | T31: =Q31*S31 -> 0 | U31: =P31*S31 -> 0
B32: 19 | C32: CONSUMO | D32: BOTA PVC CANO MEDIO Nº 40 | E32: 36025 | F32: 47317 | G32: PAR | H32: 20 | I32: 20 | J32: 0 | K32: =I32-J32 -> 20 | L32: =IF(J32<H32,"ESTOQUE BAIXO",IF(J32>I32,"ESTOQUE ALTO",IF(J32>=H32,"ESTOQUE NORMAL",))) -> ESTOQUE BAIXO | N32: =D32 -> BOTA PVC CANO MEDIO Nº 40 | O32: =SUMIFS(ENTRADA!$F:$F,ENTRADA!$B:$B,ESTOQUE!$B32) -> 26 | P32: =SUMIFS(SAIDA!$F:$F,SAIDA!$B:$B,ESTOQUE!$B32) -> 27 | Q32: =O32-P32 -> -1 | R32: =Q32=#REF! -> #REF! | S32: =IFERROR(SUMIFS(ENTRADA!$H:$H,ENTRADA!$B:$B,ESTOQUE!$B32)/O32,0) -> 8.0538462 | T32: =Q32*S32 -> -8.0538462 | U32: =P32*S32 -> 217.45385
B33: 20 | C33: CONSUMO | D33: BOTA PVC CANO MEDIO Nº 41 | E33: 36025 | F33: 47317 | G33: PAR | H33: 20 | I33: 20 | J33: =Q33 -> 14 | K33: =I33-J33 -> 6 | L33: =IF(J33<H33,"ESTOQUE BAIXO",IF(J33>I33,"ESTOQUE ALTO",IF(J33>=H33,"ESTOQUE NORMAL",))) -> ESTOQUE BAIXO | N33: =D33 -> BOTA PVC CANO MEDIO Nº 41 | O33: =SUMIFS(ENTRADA!$F:$F,ENTRADA!$B:$B,ESTOQUE!$B33) -> 27 | P33: =SUMIFS(SAIDA!$F:$F,SAIDA!$B:$B,ESTOQUE!$B33) -> 13 | Q33: =O33-P33 -> 14 | R33: =Q33=#REF! -> #REF! | S33: =IFERROR(SUMIFS(ENTRADA!$H:$H,ENTRADA!$B:$B,ESTOQUE!$B33)/O33,0) -> 18.096296 | T33: =Q33*S33 -> 253.34815 | U33: =P33*S33 -> 235.25185
A34: 0 | B34: 21 | C34: CONSUMO | D34: BOTA PVC CANO MEDIO Nº 42 | E34: 36025 | F34: 47317 | G34: PAR | H34: 20 | I34: 20 | J34: =Q34 -> 15 | K34: =I34-J34 -> 5 | L34: =IF(J34<H34,"ESTOQUE BAIXO",IF(J34>I34,"ESTOQUE ALTO",IF(J34>=H34,"ESTOQUE NORMAL",))) -> ESTOQUE BAIXO | N34: =D34 -> BOTA PVC CANO MEDIO Nº 42 | O34: =SUMIFS(ENTRADA!$F:$F,ENTRADA!$B:$B,ESTOQUE!$B34) -> 26 | P34: =SUMIFS(SAIDA!$F:$F,SAIDA!$B:$B,ESTOQUE!$B34) -> 11 | Q34: =O34-P34 -> 15 | R34: =Q34=#REF! -> #REF! | S34: =IFERROR(SUMIFS(ENTRADA!$H:$H,ENTRADA!$B:$B,ESTOQUE!$B34)/O34,0) -> 0 | T34: =Q34*S34 -> 0 | U34: =P34*S34 -> 0
B35: 22 | C35: CONSUMO | D35: BOTA PVC CANO MEDIO Nº 43 | E35: 36025 | F35: 47317 | G35: PAR | H35: 20 | I35: 20 | J35: =Q35 -> 0 | K35: =I35-J35 -> 20 | L35: =IF(J35<H35,"ESTOQUE BAIXO",IF(J35>I35,"ESTOQUE ALTO",IF(J35>=H35,"ESTOQUE NORMAL",))) -> ESTOQUE BAIXO | M35: 22 | N35: =D35 -> BOTA PVC CANO MEDIO Nº 43 | O35: =SUMIFS(ENTRADA!$F:$F,ENTRADA!$B:$B,ESTOQUE!$B35) -> 0 | P35: =SUMIFS(SAIDA!$F:$F,SAIDA!$B:$B,ESTOQUE!$B35) -> 0 | Q35: =O35-P35 -> 0 | R35: =Q35=#REF! -> #REF! | S35: =IFERROR(SUMIFS(ENTRADA!$H:$H,ENTRADA!$B:$B,ESTOQUE!$B35)/O35,0) -> 0 | T35: =Q35*S35 -> 0 | U35: =P35*S35 -> 0
B36: 23 | C36: CONSUMO | D36: BOTA PVC CANO MEDIO Nº 44 | E36: 36025 | F36: 47317 | G36: PAR | H36: 20 | I36: 20 | J36: =Q36 -> 0 | K36: =I36-J36 -> 20 | L36: =IF(J36<H36,"ESTOQUE BAIXO",IF(J36>I36,"ESTOQUE ALTO",IF(J36>=H36,"ESTOQUE NORMAL",))) -> ESTOQUE BAIXO | M36: 23 | N36: =D36 -> BOTA PVC CANO MEDIO Nº 44 | O36: =SUMIFS(ENTRADA!$F:$F,ENTRADA!$B:$B,ESTOQUE!$B36) -> 0 | P36: =SUMIFS(SAIDA!$F:$F,SAIDA!$B:$B,ESTOQUE!$B36) -> 0 | Q36: =O36-P36 -> 0 | R36: =Q36=#REF! -> #REF! | S36: =IFERROR(SUMIFS(ENTRADA!$H:$H,ENTRADA!$B:$B,ESTOQUE!$B36)/O36,0) -> 0 | T36: =Q36*S36 -> 0 | U36: =P36*S36 -> 0
B37: 24 | C37: CONSUMO | D37: BOTA PVC CANO MEDIO Nº 45 | E37: 36025 | F37: 47317 | G37: PAR | H37: 20 | I37: 20 | J37: =Q37 -> 0 | K37: =I37-J37 -> 20 | L37: =IF(J37<H37,"ESTOQUE BAIXO",IF(J37>I37,"ESTOQUE ALTO",IF(J37>=H37,"ESTOQUE NORMAL",))) -> ESTOQUE BAIXO | N37: =D37 -> BOTA PVC CANO MEDIO Nº 45 | O37: =SUMIFS(ENTRADA!$F:$F,ENTRADA!$B:$B,ESTOQUE!$B37) -> 0 | P37: =SUMIFS(SAIDA!$F:$F,SAIDA!$B:$B,ESTOQUE!$B37) -> 0 | Q37: =O37-P37 -> 0 | R37: =Q37=#REF! -> #REF! | S37: =IFERROR(SUMIFS(ENTRADA!$H:$H,ENTRADA!$B:$B,ESTOQUE!$B37)/O37,0) -> 0 | T37: =Q37*S37 -> 0 | U37: =P37*S37 -> 0
B38: 25 | C38: CONSUMO | D38: BOTA PVC CANO MEDIO Nº 46 | E38: 36025 | F38: 47317 | G38: PAR | H38: 20 | I38: 20 | J38: =Q38 -> 0 | K38: =I38-J38 -> 20 | L38: =IF(J38<H38,"ESTOQUE BAIXO",IF(J38>I38,"ESTOQUE ALTO",IF(J38>=H38,"ESTOQUE NORMAL",))) -> ESTOQUE BAIXO | M38: 24 | N38: =D38 -> BOTA PVC CANO MEDIO Nº 46 | O38: =SUMIFS(ENTRADA!$F:$F,ENTRADA!$B:$B,ESTOQUE!$B38) -> 0 | P38: =SUMIFS(SAIDA!$F:$F,SAIDA!$B:$B,ESTOQUE!$B38) -> 0 | Q38: =O38-P38 -> 0 | R38: =Q38=#REF! -> #REF! | S38: =IFERROR(SUMIFS(ENTRADA!$H:$H,ENTRADA!$B:$B,ESTOQUE!$B38)/O38,0) -> 0 | T38: =Q38*S38 -> 0 | U38: =P38*S38 -> 0
B39: 151 | C39: CONSUMO | D39: BOTINA BICO PVC Nº 39 NOBUCK | E39: N/A | F39: N/A | G39: PAR | H39: 5 | I39: 10 | J39: =Q39 -> 0 | K39: =I39-J39 -> 10 | L39: =IF(J39<H39,"ESTOQUE BAIXO",IF(J39>I39,"ESTOQUE ALTO",IF(J39>=H39,"ESTOQUE NORMAL",))) -> ESTOQUE BAIXO | M39: 25 | N39: =D39 -> BOTINA BICO PVC Nº 39 NOBUCK | O39: =SUMIFS(ENTRADA!$F:$F,ENTRADA!$B:$B,ESTOQUE!$B39) -> 11 | P39: =SUMIFS(SAIDA!$F:$F,SAIDA!$B:$B,ESTOQUE!$B39) -> 11 | Q39: =O39-P39 -> 0 | R39: =Q39=#REF! -> #REF! | S39: =IFERROR(SUMIFS(ENTRADA!$H:$H,ENTRADA!$B:$B,ESTOQUE!$B39)/O39,0) -> 0 | T39: =Q39*S39 -> 0 | U39: =P39*S39 -> 0
B40: 152 | C40: CONSUMO | D40: BOTINA BICO PVC Nº 41 NOBUCK | E40: N/A | F40: N/A | G40: PAR | H40: 5 | I40: 10 | J40: =Q40 -> 0 | K40: =I40-J40 -> 10 | L40: =IF(J40<H40,"ESTOQUE BAIXO",IF(J40>I40,"ESTOQUE ALTO",IF(J40>=H40,"ESTOQUE NORMAL",))) -> ESTOQUE BAIXO | M40: 72 | N40: =D40 -> BOTINA BICO PVC Nº 41 NOBUCK | O40: =SUMIFS(ENTRADA!$F:$F,ENTRADA!$B:$B,ESTOQUE!$B40) -> 0 | P40: =SUMIFS(SAIDA!$F:$F,SAIDA!$B:$B,ESTOQUE!$B40) -> 0 | Q40: =O40-P40 -> 0 | R40: =Q40=#REF! -> #REF! | S40: =IFERROR(SUMIFS(ENTRADA!$H:$H,ENTRADA!$B:$B,ESTOQUE!$B40)/O40,0) -> 0 | T40: =Q40*S40 -> 0 | U40: =P40*S40 -> 0
...

Sheet SAIDA
A1: DATA | B1: COD. | C1: GRUPO | D1: DESCRIÇÃO | E1: UNID | F1: QUANT | G1: Funcionario | H1: Empresa | I1: EST. MIN | J1: EST. ATUAL | K1: Observação
A2: 45253 | B2: 111 | C2: CONSUMO | D2: =IF(ISBLANK($B2),"",IFERROR(VLOOKUP($B2,ESTOQUE!$B$2:$D$97168,3,FALSE),"Produto não cadastrado")) -> LUVA DE VAQUETA MARROM | E2: =_xlfn.XLOOKUP(B2,ESTOQUE!B:B,ESTOQUE!G:G,"",0) -> PAR | F2: 9
A3: 45253 | B3: 257 | C3: CONSUMO | D3: =IF(ISBLANK($B3),"",IFERROR(VLOOKUP($B3,ESTOQUE!$B$2:$D$97168,3,FALSE),"Produto não cadastrado")) -> LUVA MULTITATO | E3: =_xlfn.XLOOKUP(B3,ESTOQUE!B:B,ESTOQUE!G:G,"",0) -> UND | F3: 10
A4: 45929 | B4: 2 | C4: CONSUMO | D4: =IF(ISBLANK($B4),"",IFERROR(VLOOKUP($B4,ESTOQUE!$B$2:$D$97168,3,FALSE),"Produto não cadastrado")) -> AVENTAL DE RASPA TAM 1X60MT | E4: =_xlfn.XLOOKUP(B4,ESTOQUE!B:B,ESTOQUE!G:G,"",0) -> UND | F4: 4
A5: 45929 | B5: 39 | C5: CONSUMO | D5: =IF(ISBLANK($B5),"",IFERROR(VLOOKUP($B5,ESTOQUE!$B$2:$D$97168,3,FALSE),"Produto não cadastrado")) -> BOTINA OP. BICO PVC Nº 41 | E5: =_xlfn.XLOOKUP(B5,ESTOQUE!B:B,ESTOQUE!G:G,"",0) -> PAR | F5: 1
A6: 45929 | B6: 40 | C6: CONSUMO | D6: =IF(ISBLANK($B6),"",IFERROR(VLOOKUP($B6,ESTOQUE!$B$2:$D$97168,3,FALSE),"Produto não cadastrado")) -> BOTINA OP. BICO PVC Nº 42 | E6: =_xlfn.XLOOKUP(B6,ESTOQUE!B:B,ESTOQUE!G:G,"",0) -> PAR | F6: 1
A7: 45929 | B7: 37 | C7: CONSUMO | D7: =IF(ISBLANK($B7),"",IFERROR(VLOOKUP($B7,ESTOQUE!$B$2:$D$97168,3,FALSE),"Produto não cadastrado")) -> BOTINA OP. BICO PVC Nº 39 | E7: =_xlfn.XLOOKUP(B7,ESTOQUE!B:B,ESTOQUE!G:G,"",0) -> PAR | F7: 1
A8: 45929 | B8: 42 | C8: CONSUMO | D8: =IF(ISBLANK($B8),"",IFERROR(VLOOKUP($B8,ESTOQUE!$B$2:$D$97168,3,FALSE),"Produto não cadastrado")) -> BOTINA OP. BICO PVC Nº 44 | E8: =_xlfn.XLOOKUP(B8,ESTOQUE!B:B,ESTOQUE!G:G,"",0) -> PAR | F8: 1
A9: 45929 | B9: 47 | C9: CONSUMO | D9: =IF(ISBLANK($B9),"",IFERROR(VLOOKUP($B9,ESTOQUE!$B$2:$D$97168,3,FALSE),"Produto não cadastrado")) -> CALÇA CINZA OP. C/ FAIXA REFLETIVA TAM: GG | E9: =_xlfn.XLOOKUP(B9,ESTOQUE!B:B,ESTOQUE!G:G,"",0) -> UND | F9: 1
A10: 45929 | B10: 49 | C10: CONSUMO | D10: =IF(ISBLANK($B10),"",IFERROR(VLOOKUP($B10,ESTOQUE!$B$2:$D$97168,3,FALSE),"Produto não cadastrado")) -> CALÇA CINZA OP. C/ FAIXA REFLETIVA TAM: P | E10: =_xlfn.XLOOKUP(B10,ESTOQUE!B:B,ESTOQUE!G:G,"",0) -> UND | F10: 2
A11: 45929 | B11: 71 | C11: CONSUMO | D11: =IF(ISBLANK($B11),"",IFERROR(VLOOKUP($B11,ESTOQUE!$B$2:$D$97168,3,FALSE),"Produto não cadastrado")) -> CAMISA LARANJA OP. C/ FAIXA REFLETIVA TAM: XG | E11: =_xlfn.XLOOKUP(B11,ESTOQUE!B:B,ESTOQUE!G:G,"",0) -> UND | F11: 1
A12: 45929 | B12: 96 | C12: CONSUMO | D12: =IF(ISBLANK($B12),"",IFERROR(VLOOKUP($B12,ESTOQUE!$B$2:$D$97168,3,FALSE),"Produto não cadastrado")) -> CINTO DE SEGURANÇA MODELO:C70 | E12: =_xlfn.XLOOKUP(B12,ESTOQUE!B:B,ESTOQUE!G:G,"",0) -> UND | F12: 1
A13: 45929 | B13: 234 | C13: CONSUMO | D13: =IF(ISBLANK($B13),"",IFERROR(VLOOKUP($B13,ESTOQUE!$B$2:$D$97168,3,FALSE),"Produto não cadastrado")) -> CONE PLASTICOR DE SINALIZACAO 75cm | E13: =_xlfn.XLOOKUP(B13,ESTOQUE!B:B,ESTOQUE!G:G,"",0) -> UND | F13: 20
... A17: 45929 | B17: 141 | C17: CONSUMO | D17: =IF(ISBLANK($B17),"",IFERROR(VLOOKUP($B17,ESTOQUE!$B$2:$D$97168,3,FALSE),"Produto não cadastrado")) -> LUVA DE VAQUETA | E17: =_xlfn.XLOOKUP(B17,ESTOQUE!B:B,ESTOQUE!G:G,"",0) -> PAR | F17: 7
A18: 45929 | B18: 189 | C18: CONSUMO | D18: =IF(ISBLANK($B18),"",IFERROR(VLOOKUP($B18,ESTOQUE!$B$2:$D$97168,3,FALSE),"Produto não cadastrado")) -> LUVA DE VAQUETA MISTA | E18: PAR | F18: 3
A19: 45929 | B19: 207 | C19: CONSUMO | D19: =IF(ISBLANK($B19),"",IFERROR(VLOOKUP($B19,ESTOQUE!$B$2:$D$97168,3,FALSE),"Produto não cadastrado")) -> LUVA POLIESTER ANTICORTE BANHADA PU TAM 9 | E19: =_xlfn.XLOOKUP(B19,ESTOQUE!B:B,ESTOQUE!G:G,"",0) -> PAR | F19: 1
A20: 45929 | B20: 144 | C20: CONSUMO | D20: =IF(ISBLANK($B20),"",IFERROR(VLOOKUP($B20,ESTOQUE!$B$2:$D$97168,3,FALSE),"Produto não cadastrado")) -> MASCARA PFF2-S C/ FILTRO | E20: =_xlfn.XLOOKUP(B20,ESTOQUE!B:B,ESTOQUE!G:G,"",0) -> UND | F20: 9
A21: 45929 | B21: 126 | C21: CONSUMO | D21: =IF(ISBLANK($B21),"",IFERROR(VLOOKUP($B21,ESTOQUE!$B$2:$D$97168,3,FALSE),"Produto não cadastrado")) -> OCULOS DE PROTEÇÃO ESCURO | E21: =_xlfn.XLOOKUP(B21,ESTOQUE!B:B,ESTOQUE!G:G,"",0) -> UND | F21: 1
A22: 45929 | B22: 124 | C22: CONSUMO | D22: =IF(ISBLANK($B22),"",IFERROR(VLOOKUP($B22,ESTOQUE!$B$2:$D$97168,3,FALSE),"Produto não cadastrado")) -> OCULOS DE PROTEÇÃO INCOLOR | E22: =_xlfn.XLOOKUP(B22,ESTOQUE!B:B,ESTOQUE!G:G,"",0) -> UND | F22: 2
A23: 45929 | B23: 129 | C23: CONSUMO | D23: =IF(ISBLANK($B23),"",IFERROR(VLOOKUP($B23,ESTOQUE!$B$2:$D$97168,3,FALSE),"Produto não cadastrado")) -> PERNEIRA DE RASPA | E23: =_xlfn.XLOOKUP(B23,ESTOQUE!B:B,ESTOQUE!G:G,"",0) -> PAR | F23: 2
A24: 45929 | B24: 130 | C24: CONSUMO | D24: =IF(ISBLANK($B24),"",IFERROR(VLOOKUP($B24,ESTOQUE!$B$2:$D$97168,3,FALSE),"Produto não cadastrado")) -> PROTETOR AUDITIVO TIPO CONCHA L-300 | E24: =_xlfn.XLOOKUP(B24,ESTOQUE!B:B,ESTOQUE!G:G,"",0) -> UND | F24: 2
A25: 45929 | B25: 139 | C25: CONSUMO | D25: =IF(ISBLANK($B25),"",IFERROR(VLOOKUP($B25,ESTOQUE!$B$2:$D$97168,3,FALSE),"Produto não cadastrado")) -> PROTETOR AURICULAR TIPO PLUG | E25: =_xlfn.XLOOKUP(B25,ESTOQUE!B:B,ESTOQUE!G:G,"",0) -> UND | F25: 4
A26: 45929 | B26: 135 | C26: CONSUMO | D26: =IF(ISBLANK($B26),"",IFERROR(VLOOKUP($B26,ESTOQUE!$B$2:$D$97168,3,FALSE),"Produto não cadastrado")) -> TALABARTE DUPLO TIPO Y | E26: =_xlfn.XLOOKUP(B26,ESTOQUE!B:B,ESTOQUE!G:G,"",0) -> UND | F26: 1
A27: 45930 | B27: 228 | C27: CONSUMO | D27: =IF(ISBLANK($B27),"",IFERROR(VLOOKUP($B27,ESTOQUE!$B$2:$D$97168,3,FALSE),"Produto não cadastrado")) -> BALACLAVA | E27: =_xlfn.XLOOKUP(B27,ESTOQUE!B:B,ESTOQUE!G:G,"",0) -> UND | F27: 5
A28: 45930 | B28: 38 | C28: CONSUMO | D28: =IF(ISBLANK($B28),"",IFERROR(VLOOKUP($B28,ESTOQUE!$B$2:$D$97168,3,FALSE),"Produto não cadastrado")) -> BOTINA OP. BICO PVC Nº 40 | E28: =_xlfn.XLOOKUP(B28,ESTOQUE!B:B,ESTOQUE!G:G,"",0) -> PAR | F28: 1
A29: 45930 | B29: 39 | C29: CONSUMO | D29: =IF(ISBLANK($B29),"",IFERROR(VLOOKUP($B29,ESTOQUE!$B$2:$D$97168,3,FALSE),"Produto não cadastrado")) -> BOTINA OP. BICO PVC Nº 41 | E29: =_xlfn.XLOOKUP(B29,ESTOQUE!B:B,ESTOQUE!G:G,"",0) -> PAR | F29: 1
A30: 45930 | B30: 242 | C30: CONSUMO | D30: =IF(ISBLANK($B30),"",IFERROR(VLOOKUP($B30,ESTOQUE!$B$2:$D$97168,3,FALSE),"Produto não cadastrado")) -> BOTINA SEGURANÇA MATATARSO 41 ADM | E30: =_xlfn.XLOOKUP(B30,ESTOQUE!B:B,ESTOQUE!G:G,"",0) -> PAR | F30: 1
... A41: 45930 | B41: 141 | C41: CONSUMO | D41: =IF(ISBLANK($B41),"",IFERROR(VLOOKUP($B41,ESTOQUE!$B$2:$D$97168,3,FALSE),"Produto não cadastrado")) -> LUVA DE VAQUETA | E41: =_xlfn.XLOOKUP(B41,ESTOQUE!B:B,ESTOQUE!G:G,"",0) -> PAR | F41: 7
A42: 45930 | B42: 189 | C42: CONSUMO | D42: =IF(ISBLANK($B42),"",IFERROR(VLOOKUP($B42,ESTOQUE!$B$2:$D$97168,3,FALSE),"Produto não cadastrado")) -> LUVA DE VAQUETA MISTA | E42: PAR | F42: 1
A43: 45930 | B43: 114 | C43: CONSUMO | D43: =IF(ISBLANK($B43),"",IFERROR(VLOOKUP($B43,ESTOQUE!$B$2:$D$97168,3,FALSE),"Produto não cadastrado")) -> LUVA LATEX NITRILICA | E43: =_xlfn.XLOOKUP(B43,ESTOQUE!B:B,ESTOQUE!G:G,"",0) -> PAR | F43: 4
A44: 45930 | B44: 207 | C44: CONSUMO | D44: =IF(ISBLANK($B44),"",IFERROR(VLOOKUP($B44,ESTOQUE!$B$2:$D$97168,3,FALSE),"Produto não cadastrado")) -> LUVA POLIESTER ANTICORTE BANHADA PU TAM 9 | E44: =_xlfn.XLOOKUP(B44,ESTOQUE!B:B,ESTOQUE!G:G,"",0) -> PAR | F44: 8
A45: 45930 | B45: 118 | C45: CONSUMO | D45: =IF(ISBLANK($B45),"",IFERROR(VLOOKUP($B45,ESTOQUE!$B$2:$D$97168,3,FALSE),"Produto não cadastrado")) -> MACACÃO DE PROTEÇÃO TYVEK | E45: =_xlfn.XLOOKUP(B45,ESTOQUE!B:B,ESTOQUE!G:G,"",0) -> UND | F45: 1
A46: 45930 | B46: 144 | C46: CONSUMO | D46: =IF(ISBLANK($B46),"",IFERROR(VLOOKUP($B46,ESTOQUE!$B$2:$D$97168,3,FALSE),"Produto não cadastrado")) -> MASCARA PFF2-S C/ FILTRO | E46: =_xlfn.XLOOKUP(B46,ESTOQUE!B:B,ESTOQUE!G:G,"",0) -> UND | F46: 45
A47: 45930 | B47: 126 | C47: CONSUMO | D47: =IF(ISBLANK($B47),"",IFERROR(VLOOKUP($B47,ESTOQUE!$B$2:$D$97168,3,FALSE),"Produto não cadastrado")) -> OCULOS DE PROTEÇÃO ESCURO | E47: =_xlfn.XLOOKUP(B47,ESTOQUE!B:B,ESTOQUE!G:G,"",0) -> UND | F47: 3
A48: 45930 | B48: 124 | C48: CONSUMO | D48: =IF(ISBLANK($B48),"",IFERROR(VLOOKUP($B48,ESTOQUE!$B$2:$D$97168,3,FALSE),"Produto não cadastrado")) -> OCULOS DE PROTEÇÃO INCOLOR | E48: =_xlfn.XLOOKUP(B48,ESTOQUE!B:B,ESTOQUE!G:G,"",0) -> UND | F48: 1
A49: 45930 | B49: 139 | C49: CONSUMO | D49: =IF(ISBLANK($B49),"",IFERROR(VLOOKUP($B49,ESTOQUE!$B$2:$D$97168,3,FALSE),"Produto não cadastrado")) -> PROTETOR AURICULAR TIPO PLUG | E49: =_xlfn.XLOOKUP(B49,ESTOQUE!B:B,ESTOQUE!G:G,"",0) -> UND | F49: 12
A50: 45930 | B50: 135 | C50: CONSUMO | D50: =IF(ISBLANK($B50),"",IFERROR(VLOOKUP($B50,ESTOQUE!$B$2:$D$97168,3,FALSE),"Produto não cadastrado")) -> TALABARTE DUPLO TIPO Y | E50: =_xlfn.XLOOKUP(B50,ESTOQUE!B:B,ESTOQUE!G:G,"",0) -> UND | F50: 1
A51: 45930 | B51: 136 | C51: CONSUMO | D51: =IF(ISBLANK($B51),"",IFERROR(VLOOKUP($B51,ESTOQUE!$B$2:$D$97168,3,FALSE),"Produto não cadastrado")) -> TAYCO CARTUCHO P/ GASES TGV-500 - MASCARA | E51: =_xlfn.XLOOKUP(B51,ESTOQUE!B:B,ESTOQUE!G:G,"",0) -> UND | F51: 1
A52: 45931 | B52: 11 | C52: CONSUMO | D52: =IF(ISBLANK($B52),"",IFERROR(VLOOKUP($B52,ESTOQUE!$B$2:$D$97168,3,FALSE),"Produto não cadastrado")) -> BOTA PVC CANO LONGO Nº 43 | E52: =_xlfn.XLOOKUP(B52,ESTOQUE!B:B,ESTOQUE!G:G,"",0) -> PAR | F52: 1
A53: 45931 | B53: 38 | C53: CONSUMO | D53: =IF(ISBLANK($B53),"",IFERROR(VLOOKUP($B53,ESTOQUE!$B$2:$D$97168,3,FALSE),"Produto não cadastrado")) -> BOTINA OP. BICO PVC Nº 40 | E53: =_xlfn.XLOOKUP(B53,ESTOQUE!B:B,ESTOQUE!G:G,"",0) -> PAR | F53: 2
...

Sheet CUSTO_TOTAL
B1: CUSTO TOTAL DE EPI - OBRA ATIAIA / PCH - UHE - CAÇU/GO
B3: TOTAL GERAL DE ENTRADAS | C3: =SUBTOTAL(9,ESTOQUE!T2:T247) -> 38325.513
B4: TOTAL GERAL DE SAIDA | C4: =SUBTOTAL(9,ESTOQUE!U2:U247) -> 105891.12
